Workbook

Sheet RESUMEN
A1: Vigilancia sanitaria - Alojamientos Temporales y Cementerios
A3: Corte de consolidación | D3: 31/08/2026
A5: CEMENTERIOS | F5: ALOJAMIENTOS TEMPORALES
A7: Cementerios consolidados | C7: Cementerios Prioridad Alta - Critico | F7: ATI | H7: ATI Alta / Crítica
A8: =COUNTA(CEMENTERIOS!A2:A500) -> 50 | B8: =COUNTA(CEMENTERIOS!A2:A500) -> 50 | C8: =COUNTIF(CEMENTERIOS!G2:G500,"Alta")+COUNTIF(CEMENTERIOS!G2:G500,"Crítica") -> 24 | D8: =COUNTIF(CEMENTERIOS!G2:G500,"Alta")+COUNTIF(CEMENTERIOS!G2:G500,"Crítica") -> 24 | F8: =COUNTA(ALOJAMIENTO_TEMPORAL!A2:A500) -> 18 | G8: =COUNTA(ALOJAMIENTO_TEMPORAL!A2:A500) -> 18 | H8: =COUNTIF(ALOJAMIENTO_TEMPORAL!N2:N500,"Alta")+COUNTIF(ALOJAMIENTO_TEMPORAL!N2:N500,"Crítica") -> 2 | I8: =COUNTIF(ALOJAMIENTO_TEMPORAL!N2:N500,"Alta")+COUNTIF(ALOJAMIENTO_TEMPORAL!N2:N500,"Crítica") -> 2
A10: Nivel de afectación - Cementerios | B10: Cantidad | F10: Prioridad sanitaria - ATI | H10: Cantidad
A11: Sin afectación | B11: =COUNTIF(CEMENTERIOS!F2:F500,"Sin afectación") -> 16 | F11: Baja | H11: =COUNTIF(ALOJAMIENTO_TEMPORAL!N2:N500,"Baja") -> 8
A12: Leve | B12: =COUNTIF(CEMENTERIOS!F2:F500,"Leve") -> 16 | F12: Media | H12: =COUNTIF(ALOJAMIENTO_TEMPORAL!N2:N500,"Media") -> 5
A13: Moderada | B13: =COUNTIF(CEMENTERIOS!F2:F500,"Moderada") -> 8 | F13: Alta | H13: =COUNTIF(ALOJAMIENTO_TEMPORAL!N2:N500,"Alta") -> 2
A14: Grave | B14: =COUNTIF(CEMENTERIOS!F2:F500,"Grave") -> 8 | F14: No concluyente | H14: =COUNTIF(ALOJAMIENTO_TEMPORAL!N2:N500,"No concluyente") -> 3
A15: Crítica | B15: =COUNTIF(CEMENTERIOS!F2:F500,"Crítica") -> 1
A16: No consignado | B16: =COUNTIF(CEMENTERIOS!F2:F500,"No consignado") -> 1
A18: Prioridad sanitaria - Cementerios | B18: Cantidad
A19: Baja | B19: =COUNTIF(CEMENTERIOS!G2:G500,"Baja") -> 13
A20: Media | B20: =COUNTIF(CEMENTERIOS!G2:G500,"Media") -> 13
A21: Alta | B21: =COUNTIF(CEMENTERIOS!G2:G500,"Alta") -> 20
A22: Crítica | B22: =COUNTIF(CEMENTERIOS!G2:G500,"Crítica") -> 4
A23: No concluyente | B23: =COUNTIF(CEMENTERIOS!G2:G500,"No concluyente") -> 0
A26: Criterio de lectura: la clasificación de afectación de cementerios se conserva como dato fuente. La 'prioridad sanitaria' es una clasificación operativa de seguimiento construida para este proyecto, considerando exposición de restos, bóvedas abiertas, riesgo de colapso, señalización/restricción, agua, residuos y otros hallazgos. En ATI se valoran por separado Locativo/EIS, Alimentos y Vectores; los vacíos se mantienen como 'No evaluado/No concluyente' y no se convierten en respuestas negativas.

Sheet CEMENTERIOS
A1: ID | B1: ARO | C1: MUNICIPIO | D1: FECHA VISITA | E1: CEMENTERIO | F1: NIVEL AFECTACIÓN FUENTE | G1: PRIORIDAD SANITARIA | H1: RESTRICCIÓN/CIERRE | I1: EXPOSICIÓN RESTOS | J1: RIESGO COLAPSO | K1: BÓVEDAS ABIERTAS | L1: AGUA | M1: GESTIÓN RESIDUOS | N1: CONDICIÓN SALUD PÚBLICA | O1: COMPLETITUD % | P1: N.º FOTOS | Q1: DAÑOS/HALLAZGOS PRINCIPALES | R1: OBSERVACIONES | S1: FUENTE PRINCIPAL | T1: TIPO DE FUENTE
A2: CEM-001 | B2: ARO SUR - CALI | C2: FLORIDA | D2: 46248 | E2: CEMENTERIO CIVIL IGLESIA UNION MISIONERA EVANGELICA COLOMBIANA | F2: SIN AFECTACIÓN | G2: BAJA | H2: NO | I2: NO | J2: NO | K2: NO | L2: SI | M2: SI | N2: NO | O2: 100 | P2: 0 | Q2: NO | S2: CUADRO CEMENTERIOS TOTALES-21082026.XLSX | T2: EXCEL RESUMEN
A3: CEM-002 | B3: ARO SUR - CALI | C3: LA CUMBRE | D3: 46247 | E3: CEMENTERIO COMUNITARIO SAN JOSE PAVAS | F3: MODERADA | G3: MEDIA | H3: SI | I3: NO | J3: SI | K3: NO | L3: NO | M3: SI | N3: NO | O3: 100 | P3: 3 | Q3: SI | S3: CUADRO CEMENTERIOS TOTALES-21082026.XLSX | T3: EXCEL RESUMEN
A4: CEM-003 | B4: ARO SUR - CALI | C4: VIJES | D4: 46248 | E4: CEMENTERIO CRISTO RESUCITADO | F4: MODERADA | G4: ALTA | H4: SI | I4: SI | J4: NO | K4: NO | L4: SI | M4: SI | N4: SI | O4: 100 | P4: 3 | Q4: SI | S4: CUADRO CEMENTERIOS TOTALES-21082026.XLSX | T4: EXCEL RESUMEN
A5: CEM-004 | B5: ARO SUR - CALI | C5: GUACARI | D5: 46248 | E5: CEMENTERIO CRISTO REY | F5: MODERADA | G5: ALTA | H5: SI | I5: SI | J5: NO | K5: SI | L5: SI | M5: SI | N5: SI | O5: 100 | P5: 1 | Q5: SI | S5: CUADRO CEMENTERIOS TOTALES-21082026.XLSX | T5: EXCEL RESUMEN
A6: CEM-005 | B6: ARO SUR - CALI | C6: FLORIDA | D6: 46248 | E6: CEMENTERIO SAN ANTONIO DE PAUDA | F6: SIN AFECTACIÓN | G6: BAJA | H6: NO | I6: NO | J6: NO | K6: NO | L6: SI | M6: SI | N6: NO | O6: 100 | P6: 0 | Q6: NO | S6: CUADRO CEMENTERIOS TOTALES-21082026.XLSX | T6: EXCEL RESUMEN
A7: CEM-006 | B7: ARO SUR - CALI | C7: EL CERRITO | D7: 46248 | E7: CEMENTERIO SAN PEDRO APOSTOL SANTA ELENA | F7: SIN AFECTACIÓN | G7: BAJA | H7: NO | I7: NO | J7: NO | K7: NO | L7: SI | M7: SI | N7: NO | O7: 100 | P7: 2 | Q7: NO | S7: CUADRO CEMENTERIOS TOTALES-21082026.XLSX | T7: EXCEL RESUMEN
A8: CEM-007 | B8: ARO SUR - CALI | C8: EL CERRITO | D8: 46248 | E8: CEMENTERIO SAGRADO CORAZÓN DE JESUS | F8: SIN AFECTACIÓN | G8: BAJA | H8: NO | I8: NO | J8: NO | K8: NO | L8: SI | M8: NO | N8: NO | O8: 100 | P8: 0 | Q8: NO | S8: CUADRO CEMENTERIOS TOTALES-21082026.XLSX | T8: EXCEL RESUMEN
A9: CEM-008 | B9: ARO SUR - CALI | C9: EL CERRITO | D9: 46248 | E9: CEMENTERIO CENTRAL | F9: LEVE | G9: MEDIA | H9: SI | I9: NO | J9: SI | K9: NO | L9: SI | M9: SI | O9: 91 | P9: 0 | Q9: NO | S9: CUADRO CEMENTERIOS TOTALES-21082026.XLSX | T9: EXCEL RESUMEN
A10: CEM-009 | B10: ARO SUR - CALI | C10: LA CUMBRE | D10: 46248 | E10: CEMENTERIO COMUNITARIO DE PAZ BITACO | F10: GRAVE | G10: ALTA | J10: SI | O10: 18 | P10: 0 | S10: CUADRO CEMENTERIOS TOTALES-21082026.XLSX | T10: EXCEL RESUMEN
A11: CEM-010 | B11: ARO SUR - CALI | C11: LA CUMBRE | D11: 46248 | E11: CEMENTARIO LOMITAS | F11: GRAVE | G11: CRÍTICA | I11: SI | K11: SI | O11: 27 | P11: 0 | S11: CUADRO CEMENTERIOS TOTALES-21082026.XLSX | T11: EXCEL RESUMEN
A12: CEM-011 | B12: ARO SUR - CALI | C12: LA CUMBRE | D12: 46248 | E12: CEMENTARIO CRISTIANO ENMANUEL | F12: SIN AFECTACIÓN | G12: BAJA | I12: NO | K12: NO | O12: 27 | P12: 0 | S12: CUADRO CEMENTERIOS TOTALES-21082026.XLSX | T12: EXCEL RESUMEN
A13: CEM-012 | B13: ARO SUR - CALI | C13: LA CUMBRE | D13: 46248 | E13: CEMENTERIO JARDINES DE LA PAZ PUENTE PALO | F13: GRAVE | G13: ALTA | I13: NO | J13: SI | K13: NO | O13: 36 | P13: 0 | S13: CUADRO CEMENTERIOS TOTALES-21082026.XLSX | T13: EXCEL RESUMEN
A14: CEM-013 | B14: ARO SUR - CALI | C14: PRADERA | D14: 46248 | E14: CEMENTERIO CRISTO REY | F14: SIN AFECTACIÓN | G14: BAJA | H14: NO | I14: NO | J14: NO | K14: NO | L14: SI | M14: SI | N14: NO | O14: 100 | P14: 0 | Q14: NO | S14: CUADRO CEMENTERIOS TOTALES-21082026.XLSX | T14: EXCEL RESUMEN
A15: CEM-014 | B15: ARO SUR - CALI | C15: FLORIDA | D15: 46248 | E15: CEMENTERIO SAN ANTONIO DE PADUA-SAN ANTONIO DE LOS CABALLEROS | F15: SIN AFECTACIÓN | G15: BAJA | H15: NO | I15: NO | J15: NO | K15: NO | L15: SI | M15: SI | N15: NO | O15: 100 | P15: 0 | Q15: NO | S15: CUADRO CEMENTERIOS TOTALES-21082026.XLSX | T15: EXCEL RESUMEN
A16: CEM-015 | B16: ARO SUR - CALI | C16: GINEBRA | D16: 46249 | E16: CEMENTERIO PARROQUIAL NUESTRA SEÑORA DEL ROSARIO | F16: MODERADA | G16: ALTA | H16: SI | I16: NO | J16: SI | K16: NO | L16: SI | M16: SI | N16: NO | O16: 100 | P16: 0 | Q16: NO | S16: CUADRO CEMENTERIOS TOTALES-21082026.XLSX | T16: EXCEL RESUMEN
A17: CEM-016 | B17: ARO SUR - CALI | C17: GINEBRA | D17: 46249 | E17: CEMENTERIO CATOLICO COSTA RICA-GINEBRA | F17: SIN AFECTACIÓN | G17: BAJA | H17: NO | I17: NO | J17: NO | K17: NO | L17: SI | M17: SI | N17: NO | O17: 100 | P17: 1 | Q17: NO | S17: CUADRO CEMENTERIOS TOTALES-21082026.XLSX | T17: EXCEL RESUMEN
A18: CEM-017 | B18: ARO SUR - CALI | C18: GINEBRA | D18: 46249 | E18: CEMENTERIO VILLA DE PAZ | F18: SIN AFECTACIÓN | G18: BAJA | H18: NO | I18: NO | J18: NO | K18: NO | L18: SI | M18: SI | N18: NO | O18: 100 | P18: 0 | Q18: NO | S18: CUADRO CEMENTERIOS TOTALES-21082026.XLSX | T18: EXCEL RESUMEN
A19: CEM-018 | B19: ARO SUR - CALI | C19: DAGUA | D19: 46249 | E19: CEMENTERIO EL PALMAR | F19: SIN AFECTACIÓN | G19: BAJA | I19: NO | J19: NO | K19: NO | O19: 27 | P19: 0 | S19: CUADRO CEMENTERIOS TOTALES-21082026.XLSX | T19: EXCEL RESUMEN
A20: CEM-019 | B20: ARO SUR - CALI | C20: DAGUA | D20: 46249 | E20: CEMENTERIO LAS BRISAS | F20: GRAVE | G20: ALTA | I20: NO | J20: SI | K20: NO | O20: 36 | P20: 0 | S20: CUADRO CEMENTERIOS TOTALES-21082026.XLSX | T20: EXCEL RESUMEN
A21: CEM-020 | B21: ARO SUR - CALI | C21: DAGUA | D21: 46249 | E21: CEMENTERIO CAMPOSANTO CATOLICO - CORREGIMIENTO VILLA HERMOSA | F21: LEVE | G21: MEDIA | I21: NO | J21: SI | O21: 36 | P21: 0 | S21: CUADRO CEMENTERIOS TOTALES-21082026.XLSX | T21: EXCEL RESUMEN
A22: CEM-021 | B22: ARO SUR - CALI | C22: EL CERRITO | D22: 46252 | E22: CEMENTERIO EL POMO | F22: SIN AFECTACIÓN | G22: BAJA | H22: NO | I22: NO | J22: NO | K22: NO | L22: SI | M22: SI | N22: NO | O22: 100 | P22: 1 | Q22: NO | S22: CUADRO CEMENTERIOS TOTALES-21082026.XLSX | T22: EXCEL RESUMEN
A23: CEM-022 | B23: ARO SUR - CALI | C23: DAGUA | D23: 46252 | E23: CEMENTERIO DE LA PARROQUIA SAN ISIDRO LABRADOR | F23: GRAVE | G23: ALTA | H23: SI | I23: SI | L23: NO | O23: 55 | P23: 0 | Q23: NO | S23: CUADRO CEMENTERIOS TOTALES-21082026.XLSX | T23: EXCEL RESUMEN
A24: CEM-023 | B24: ARO SUR - CALI | C24: DAGUA | D24: 46252 | E24: CEMENTERIO CATOLICO DEL QUEREMAL - PARROQUIA SAN JOSE DEL QUEREMAL - DAGUA | F24: LEVE | G24: MEDIA | H24: NO | I24: NO | K24: SI | L24: SI | O24: 64 | P24: 0 | Q24: SI | S24: CUADRO CEMENTERIOS TOTALES-21082026.XLSX | T24: EXCEL RESUMEN
A25: CEM-024 | B25: ARO SUR - CALI | C25: DAGUA | D25: 46252 | E25: CEMENTERIO EL LIMONAR - DAGUA | F25: LEVE | G25: MEDIA | I25: NO | K25: NO | L25: NO | M25: NO | N25: NO | O25: 73 | P25: 0 | Q25: NO | S25: CUADRO CEMENTERIOS TOTALES-21082026.XLSX | T25: EXCEL RESUMEN
A26: CEM-025 | B26: ARO SUR - CALI | C26: DAGUA | D26: 46252 | E26: CEMENTERIO SAN JOSE DEL SALADO - DAGUA | F26: LEVE | G26: MEDIA | H26: NO | I26: NO | J26: NO | K26: NO | L26: NO | M26: NO | N26: NO | O26: 91 | P26: 1 | Q26: NO | S26: CUADRO CEMENTERIOS TOTALES-21082026.XLSX | T26: EXCEL RESUMEN
A27: CEM-026 | B27: ARO SUR - CALI | C27: DAGUA | D27: 46254 | E27: CEMENTERIO JUNTA ACCION COMUNAL CORREGIMIENTO EL CARMEN | F27: SIN AFECTACIÓN | G27: BAJA | H27: NO | I27: NO | K27: NO | L27: SI | M27: SI | N27: NO | O27: 91 | P27: 0 | Q27: SI (YA FUERON REPARADOS) | S27: CUADRO CEMENTERIOS TOTALES-21082026.XLSX | T27: EXCEL RESUMEN
A28: CEM-027 | B28: ARO CENTRO - TULUÁ | C28: CAICEDONIA | D28: 46248 | E28: CEMENTERIO LOCAL DE CAICEDONIA | F28: LEVE | G28: ALTA | H28: SI, ZONA DE OSARIOS CON RESTOS EXPUESTOS | I28: NO | J28: PARED INTERIOR DE OSARIOS | K28: NO | L28: SI | M28: SI | N28: SI, EXPOSICIÓN DE RESTOS EN ALGUNOS OSARIOS QUE SUFRIERON DAÑOS | O28: 100 | P28: 0 | Q28: SI | R28: SE VERIFICÓ CONDICIONES HIGIÉNICO SANITARIAS Y LOCATIVAS EVIDENCIANDO LO SGUIENTE: DAÑO ESTRUCTURAL EN PARED POSTERIOR Y TEJAS. ALGUNAS GRIETAS NE PAREDES Y TECHOS. SE CAYÓ UNA PARED CON OSARIOS LOS CUALES QUEDARON EXPUESTOS POR RESTOS, EL ARREGLO SE REALIZARÁ EL 17 DE AGOSTO. SUMINISTRO DE AGUA NORMAL | S28: CUADRO CEMENTERIOS TOTALES-21082026.XLSX | T28: EXCEL RESUMEN
A29: CEM-028 | B29: ARO CENTRO - TULUÁ | C29: BOLÍVAR | D29: 46248 | E29: CEMENTERIO CENTRAL SANTA ANA | F29: LEVE | G29: MEDIA | J29: SI, EN LA CAPILLA | O29: 18 | P29: 0 | Q29: SI, EN LA CAPILLA | R29: SE PRESENTÓ EXPOSICIÓN DE 2 BÓVEDAS Y 31 OSARIOS, SIN EMBARGO, EN EL MOMENTO DE LA VISITA, SE HABÍA REALIZADO LOS ARREGLOS RESPECTIVOS | S29: CUADRO CEMENTERIOS TOTALES-21082026.XLSX | T29: EXCEL RESUMEN
A30: CEM-029 | B30: ARO CENTRO - TULUÁ | C30: CALIMA | D30: 46248 | E30: CEMENTERIO JARDÍN DE LA VIDA | F30: LEVE | G30: ALTA | I30: NO | J30: SI, EN LA CAPILLA | K30: SI, 2 LÁPIDAS DE SEPULTURAS AGRIETADAS DE FORMA SUPERFICIAL | L30: SI | M30: SI | N30: LAS AFECTACIONES FUERON LA CAPILLA Y EN LA ESTRUCTURA DE LA ANTÍGUA ENTRADA, POR LO QUE SE ENCUENTRAN SEÑALIZADAS E INHABILITADAS | O30: 82 | P30: 4 | Q30: SI, AFECTACIÓN EN TECHO DE LA CAPILLA (DESPRENDIMIENTO DE MATERIAL Y TEJAS CAÍDAS Y DAÑO EN LA ESTRUCTURA DE LA ANTÍGUA ENTRADA, AMBAS INHABILITADAS) | S30: CUADRO CEMENTERIOS TOTALES-21082026.XLSX | T30: EXCEL RESUMEN
A31: CEM-030 | B31: ARO CENTRO - TULUÁ | C31: ZARZAL | D31: 46247 | E31: CEMENTERIO CATÓLICO MUNICIPAL | F31: LEVE | G31: ALTA | I31: NO | J31: SI, EN LA ENTRADA AL ESTABLECIMIENTO Y LA PARED COLINDANTE CON EL BATALLÓN | K31: SI, LÁPIDAS DETERIORADAS SIN EXPOSICIÓN ÓSEA | L31: SI | M31: SI | N31: NO | O31: 91 | P31: 2 | Q31: SI, EN LA ENTRADA AL ESTABLECIMIENTO Y PARED QUE COLINDA CON EL BATALLÓN. GRIETA EN LA PARTE LATERAL | S31: CUADRO CEMENTERIOS TOTALES-21082026.XLSX | T31: EXCEL RESUMEN
A32: CEM-031 | B32: ARO CENTRO - TULUÁ | C32: SEVILLA | D32: 46248 | E32: CEMENTERIO CATÓLICO SAN LUIS GONZAGA | F32: GRAVE | G32: CRÍTICA | I32: SI | J32: SI, BÓVEDAS Y MUROS | K32: SI | L32: NO MENCIONA | M32: NO MENCIONA | N32: SI, HAY EXPOSICIÓN DE RESTOS DE LAS BÓVEDAS | O32: 91 | P32: 0 | Q32: SE OBSERVA EN LA PARTE FRONTAL DEL CEMENTERIO, MUROS CAÍDOS QUE AFECTAN BÓVEDAS, LINDERO CON PARQUEADERO DONDE CAEN LOS RESTOS DE LAS BÓVEDAS, PARTE TRASERA Y PARTE SUR TAMBIÉN CON CAÍDA DE MUROS. AFECTACIÓN DE 35 BÓVEDAS | S32: CUADRO CEMENTERIOS TOTALES-21082026.XLSX | T32: EXCEL RESUMEN
A33: CEM-032 | B33: ARO CENTRO - TULUÁ | C33: YOTOCO | D33: 46252 | E33: CEMENTERIO PARROQUIA INMACULADA CONCEPCIÓN | F33: GRAVE | G33: ALTA | H33: SI, EL ÁREA DE LA CAPILLA | I33: NO | J33: SI, SE EVIDENCIA MURO EN ÁREA DE CAPILLA CON RIESGO DE DESPRENDIMIENTO, CERRAMIENTO AGRIETADO | K33: NO | L33: SI | M33: SI | N33: NO, LAS GRIETAS Y EL ÁREA DE LA CAPILLA SON LAS AFECTADAS | O33: 100 | P33: 8 | Q33: SE EVIDENCIA MURO EN ÁREA DE CAPILLA CON RIESGO DE DESPRENDIMIENTO, CERRAMIENTO AGRIETADO, ÁREA DELIMITADA CON CINTA AMARILLA PERO NO ESTÁ DELIMITADA EL ÁREA DE CAPILLA, INGRESO DE PÚBLICO RESTRINGIDO PERO EL SERVICIO DE INHUMACIÓN SE SIGUE PRESTANDO, VÍAS INTERNAS CON INGRESO SEGURO, HAY MUROS Y PISOS AGRIETADOS, SOLO AGRIETAMIENTOS PARCIALES EN EL ÁREA DE BÓVEDAS | S33: CUADRO CEMENTERIOS TOTALES-21082026.XLSX | T33: EXCEL RESUMEN
A34: CEM-033 | B34: ARO CENTRO - TULUÁ | C34: YOTOCO | D34: 46252 | E34: CEMENTERIO CIVIL YOTOCO | F34: SIN AFECTACIÓN | G34: MEDIA | H34: NO | I34: NO | J34: NO | K34: NO | L34: NO HAY SUMINISTRO | M34: NO | N34: NO | O34: 100 | P34: 3 | Q34: NO SE PRESENTARON PERSONAS LESIONADAS, LOS SERVICIOS DE INHUMACIÓN FUERON SUSPENDIDOS DESDE LA PANDEMIA, , NO SE EVIDENCIAN ESTRUCTURAS CON RIESGO DE DESPRENDIMIENTO, NO REQUIERE SEÑALIZACIÓN, LAS VÍAS INTERNAS SON EN TIERRA Y NO PRESENTAN NOVEDADES, NO HAY DAÑOS ESTRUCTURALES EN MUROS NI CUBIERTAS, NO HAY ÁREA DE BÓVEDAS, NO HAY EXPOSICIÓN DE ATAÚDES NI RESTOS HUMANOS, NO HAY SUMINISTRO DE AGUA POTABLE, EL PISO ES EN TIERRA Y TIENE MALEZA , EL ASEO ES MENSUAL E INADECUADO, | S34: CUADRO CEMENTERIOS TOTALES-21082026.XLSX | T34: EXCEL RESUMEN
A35: CEM-034 | B35: ARO CENTRO - TULUÁ | C35: RIOFRÍO | D35: 46247 | E35: CEMENTERIO SANTA MARÍA MAGDALENA | F35: LEVE | G35: MEDIA | H35: NO | I35: NO | J35: NO | K35: NO | L35: SI, ES DE POZO PROFUNDO | M35: SI | N35: NO | O35: 100 | P35: 0 | Q35: SI | S35: CUADRO CEMENTERIOS TOTALES-21082026.XLSX | T35: EXCEL RESUMEN
A36: CEM-035 | B36: ARO CENTRO - TULUÁ | C36: RIOFRÍO | D36: 46248 | E36: CEMENTERIO LA SANTÍSIMA TRINIDAD/SAN MIGUEL | F36: SIN AFECTACIÓN | G36: MEDIA | H36: NO | I36: NO | J36: NO | K36: SOLO HAY UNA LÁPIDA DE BÓVEDA DESPRENDIDA PERO AL PARECER ES POR EL DESGASTE, COMO CONSECUENCIA DEL SISMO | L36: NO TIENE SUMINISTRO DE AGUA | M36: NO SE EVIDENCIA ÁREA PARA EL ALMACENAMIENTO DE LOS RESIDUOS | N36: NO | O36: 100 | P36: 0 | Q36: NO | S36: CUADRO CEMENTERIOS TOTALES-21082026.XLSX | T36: EXCEL RESUMEN
A37: CEM-036 | B37: ARO NORTE - CARTAGO | C37: OBANDO | D37: 46247 | E37: CEMENTERIO SAN JOSÉ | F37: LEVE | G37: ALTA | H37: SI, EL ÁREA DE LA CAPILLA | I37: NO MENCIONA | J37: SI, EN EL TECHO DE LA CAPILLA | K37: NO | L37: NO MENCIONA | M37: NO MENCIONA | N37: NO | O37: 100 | P37: 2 | Q37: SI, ESTRUCTURALES EN EL TECHO DE LA CAPILLA | S37: CUADRO CEMENTERIOS TOTALES-21082026.XLSX | T37: EXCEL RESUMEN
A38: CEM-037 | B38: ARO NORTE - CARTAGO | C38: VERSALLES | D38: 46249 | E38: CEMENTERIO MUNICIPAL CATÓLICO DE VERSALLES | F38: MODERADA | G38: ALTA | H38: SI, EL ÁREA DE OSARIOS | I38: SI | J38: SI, EN LA PARTE INFERIOR DE UNOS DE LOS BLOQUE | K38: SI | L38: SI | M38: SI | N38: SI, HAY EXPOSICIÓN DE RESTOS HUMANOS | O38: 100 | P38: 7 | Q38: SI, ESTRUCTURA DE LOS OSARIOS, GRIETAS, COLAPSO PARCIAL DE LA PARTE INFERIOR DE UNO DE LOS BLOQUES, DESPRENDIMIENTO DE TAPAS Y ELEMENTOS ESTRUCTURALES EN OTROS SECTORES DEJANDO RESTOS EXPUESTOS | S38: CUADRO CEMENTERIOS TOTALES-21082026.XLSX | T38: EXCEL RESUMEN
A39: CEM-038 | B39: ARO NORTE - CARTAGO | C39: ULLOA | D39: 46248 | E39: CEMENTERIO SAN JOSÉ DE ULLOA | F39: MODERADA | G39: ALTA | H39: SI, EL ÁREA DE BÓVEDAS | I39: SI, DE ATAUDES | J39: SI, LAS COLUMNAS SE ENCUENTRAN EN RIESGO DE COLAPSO | K39: SI | L39: NO MENCIONA | M39: NO MENCIONA | N39: SÍ, SE GENERARON GRIETAS EN BÓVEDAS, CAÍDA DE TAPAS CON LÁPIDAS, MUSOLEO CON DETERIORO DEBIDO A QUE UNA DE LAS PAREDES PRESENTA GRIETAS. SE EVIDENCIA APERTURA DE TAPAS DE LAS BÓVEDAS QUE PERMITEN VER EL COFRE PERO NO LOS RESTOS, LAS COLUMNAS SE ENCUENTRAN FISURADAS Y CON PESO DE LA PARTE SUPERIOR PUEDEN COLAPSAR. | O39: 100 | P39: 0 | Q39: SE GENERARON GRIETAS EN BÓVEDAS, CAÍDA DE TAPAS CON LÁPIDAS, MUSOLEO CON DETERIORO DEBIDO A QUE UNA DE LAS PAREDES PRESENTA GRIETAS. SE EVIDENCIA APERTURA DE TAPAS DE LAS BÓVEDAS QUE PERMITEN VER EL COFRE PERO NO LOS RESTOS, LAS COLUMNAS SE ENCUENTRAN FISURADAS Y CON PESO DE LA PARTE SUPERIOR PUEDEN COLAPSAR. | S39: CUADRO CEMENTERIOS TOTALES-21082026.XLSX | T39: EXCEL RESUMEN
A40: CEM-039 | B40: ARO NORTE - CARTAGO | C40: LA VICTORIA | D40: 46247 | E40: CEMENTERIO CATÓLICO SAN JOSÉ | F40: MODERADA | G40: ALTA | H40: SI, PAREA DE BÓVEDAS Y CAPILLA | I40: NO | J40: SI, DESPRENDIMIENTO DE ALGUNAS TEJAS DE LA CUBIERTA SOBRE LAS BÓVEDAS Y PRESENCIA DE FISURAS VISIBLES EN ÁREA DE CAPILLA | K40: NO | L40: SI | M40: SI | N40: SI, DESPRENDIMIENTO DE ALGUNAS TEJAS DE LA CUBIERTA SOBRE LAS BÓVEDAS Y PRESENCIA DE FISURAS VISIBLES EN ÁREA DE CAPILLA | O40: 100 | P40: 0 | Q40: SI, DESPRENDIMIENTO DE ALGUNAS TEJAS DE LA CUBIERTA SOBRE LAS BÓVEDAS Y PRESENCIA DE FISURAS VISIBLES EN ÁREA DE CAPILLA | S40: CUADRO CEMENTERIOS TOTALES-21082026.XLSX | T40: EXCEL RESUMEN
...

Sheet ALOJAMIENTO_TEMPORAL
A1: ID | B1: ARO | C1: Municipio | D1: Alojamiento temporal / ATI | E1: Estado operativo | F1: Última visita | G1: Población última | H1: Locativo/EIS - estado | I1: Locativo/EIS - prioridad | J1: Alimentos - estado | K1: Alimentos - prioridad | L1: Vectores - estado | M1: Vectores - prioridad | N1: Prioridad global | O1: Cobertura líneas % | P1: N.º visitas | Q1: N.º fotos | R1: Agua / saneamiento | S1: Alimentos - observación | T1: Vectores - observación | U1: Observaciones | V1: Fuente última
A2: ATI-001 | B2: ARO NORTE - CARTAGO | C2: ANSERMANUEVO | D2: ALCALDÍA MUNICIPAL DE ANSERMANUEVO | E2: OCUPADO AL MOMENTO DE LA VISITA | F2: 46255 | G2: 25 | H2: SIN HALLAZGOS RELEVANTES | I2: BAJA | J2: SIN HALLAZGOS RELEVANTES | K2: BAJA | L2: SIN HALLAZGOS RELEVANTES | M2: BAJA | N2: BAJA | O2: 100 | P2: 1 | Q2: 0 | R2: SÍ | ALCANTARILLADO MUNICIPAL | BATERÍAS: 6 | S2: ÁREA DE PREPARACIÓN EVALUADA SIN HALLAZGO CRÍTICO DOCUMENTADO. | T2: SIN AGRESIONES ANIMALES NI PRESENCIA DE PLAGAS/ROEDORES DOCUMENTADA. | U2: POBLACIÓN APROXIMADA Y VARIABLES SANITARIAS TRANSCRITAS DE LISTA DE CHEQUEO DIRECTA DEL 21/08. | V2: ALBERGUE TEMPORAL ALCALDIA MUNICIPAL, MUNICIPIO ANSERMANUEVO.21-08-2026.PDF
A3: ATI-002 | B3: ARO NORTE - CARTAGO | C3: ANSERMANUEVO | D3: PARQUE RECREACIONAL | E3: HABILITADO SIN OCUPACIÓN AL REGISTRO | F3: 46246 | G3: 0 | H3: NO EVALUADO | I3: NO CONCLUYENTE | J3: NO EVALUADO | K3: NO CONCLUYENTE | L3: NO EVALUADO | M3: NO CONCLUYENTE | N3: NO CONCLUYENTE | O3: 0 | P3: 1 | Q3: 0 | R3: NO DOCUMENTADO | | BATERÍAS: | S3: SIN INFORMACIÓN SUFICIENTE SOBRE PREPARACIÓN/MANIPULACIÓN DE ALIMENTOS. | T3: SIN INFORMACIÓN SUFICIENTE SOBRE VECTORES/ZOONOSIS. | U3: EL MUNICIPIO REGISTRÓ SEGUIMIENTO POSTERIOR EN ALCALDÍA MUNICIPAL. | V3: REGISTRO EIS / CARPETA MUNICIPAL ANSERMANUEVO
A4: ATI-003 | B4: ARO CENTRO - TULUÁ | C4: CAICEDONIA | D4: COLISEO CIC - CAICEDONIA | E4: OCUPADO AL MOMENTO DE LA VISITA | F4: 46248 | G4: 9 | H4: SIN HALLAZGOS RELEVANTES | I4: BAJA | J4: SIN HALLAZGOS RELEVANTES | K4: BAJA | L4: SIN HALLAZGOS RELEVANTES | M4: BAJA | N4: BAJA | O4: 100 | P4: 1 | Q4: 0 | R4: SI | | BATERÍAS: 2 | S4: ÁREA DE PREPARACIÓN EVALUADA SIN HALLAZGO CRÍTICO DOCUMENTADO. | T4: SIN AGRESIONES ANIMALES NI PRESENCIA DE PLAGAS/ROEDORES DOCUMENTADA. | U4: ALBERGA A PERSONAS, LA ALIMENTACIÓN ES SUMINISTRADA POR LA ALCALDÍA, DESARROLLO SOCIAL, A TRAVÉS DEL ANCIANATO. FUNCIONA EN EL COLISEO CIC, TIENE AGUA POTABLE Y RECOLECCIÓN DE RESIDUOS | V4: REGISTRO DE ESTADO SANITARIO DE ESTABLECIMIENTOS.XLSX
A5: ATI-004 | B5: ARO CENTRO - TULUÁ | C5: CALIMA | D5: CIC - CENTRO DE INTEGRACIÓN CIUDADANA | E5: OCUPADO AL MOMENTO DE LA VISITA | F5: 46248 | G5: 50 | H5: SIN HALLAZGOS RELEVANTES | I5: BAJA | J5: HALLAZGO RELEVANTE | K5: ALTA | L5: SIN HALLAZGOS RELEVANTES | M5: BAJA | N5: ALTA | O5: 100 | P5: 2 | Q5: 5 | R5: SI | | BATERÍAS: 6 | S5: SE DOCUMENTA AUSENCIA DE LAVADO DE MANOS DURANTE EL MANEJO/PREPARACIÓN. | T5: SIN AGRESIONES ANIMALES NI PRESENCIA DE PLAGAS/ROEDORES DOCUMENTADA. | U5: ELEMENTOS DE PROTECCIÓN PERSONAL INCOMPLETOS Y NO SE REALIZA LAVADO DE MANOS | V5: REGISTRO DE ESTADO SANITARIO DE ESTABLECIMIENTOS.XLSX
A6: ATI-005 | B6: ARO NORTE - CARTAGO | C6: EL ÁGUILA | D6: COLEGIO PARROQUIAL EL ÁGUILA | E6: OCUPADO AL MOMENTO DE LA VISITA | F6: 46252 | G6: 9 | H6: SIN HALLAZGOS RELEVANTES | I6: BAJA | J6: SIN PREPARACIÓN EN SITIO | K6: BAJA | L6: SIN HALLAZGOS RELEVANTES | M6: BAJA | N6: BAJA | O6: 100 | P6: 1 | Q6: 0 | R6: SÍ | ALCANTARILLADO | BATERÍAS: 4 | S6: LOS ALIMENTOS SE PREPARAN FUERA DEL ALOJAMIENTO O NO EXISTE PREPARACIÓN EN SITIO. | T6: SIN AGRESIONES ANIMALES NI PRESENCIA DE PLAGAS/ROEDORES DOCUMENTADA. | U6: DATOS TRANSCRITOS DE LISTA DE CHEQUEO DIRECTA. DISTRIBUCIÓN POR SEXO/EDAD TOMADA DE LECTURA VISUAL DEL FORMATO. | V6: ALBERGUE TEMPORAL COLEGIO PARROQUIAL, MUNICIPIO DEL AGUILA.18-08-2026.PDF
A7: ATI-006 | B7: ARO NORTE - CARTAGO | C7: LA UNIÓN | D7: COLISEO ANGELINO GARZÓN | E7: OCUPADO AL MOMENTO DE LA VISITA | F7: 46246 | G7: 40 | H7: SIN HALLAZGOS RELEVANTES | I7: BAJA | J7: SIN PREPARACIÓN EN SITIO | K7: BAJA | L7: SIN HALLAZGOS RELEVANTES | M7: BAJA | N7: BAJA | O7: 100 | P7: 1 | Q7: 5 | R7: SI | | BATERÍAS: 2 | S7: LOS ALIMENTOS SE PREPARAN FUERA DEL ALOJAMIENTO O NO EXISTE PREPARACIÓN EN SITIO. | T7: SIN AGRESIONES ANIMALES NI PRESENCIA DE PLAGAS/ROEDORES DOCUMENTADA. | U7: LOS INSUMOS PARA LIMPIEZA Y DESINFECCIÓN LOS TRAEN DESDE LA ALCALDÍA Y NO SE ALMACENAN EN EL LUGAR. LOS ALIMENTOS SON SUMINISTRADOS YA PREPARADOS EMPACADOS EN DESECHABLES Y SE DISTRIBUYEN PARA SU INMEDIATO CONSUMO | V7: REGISTRO DE ESTADO SANITARIO DE ESTABLECIMIENTOS.XLSX
A8: ATI-007 | B8: ARO NORTE - CARTAGO | C8: LA VICTORIA | D8: COLISEO CIC - VILLA MARIANA | E8: OCUPADO AL MOMENTO DE LA VISITA | F8: 46246 | G8: 16 | H8: SIN HALLAZGOS RELEVANTES | I8: BAJA | J8: SIN PREPARACIÓN EN SITIO | K8: BAJA | L8: SIN HALLAZGOS RELEVANTES | M8: BAJA | N8: BAJA | O8: 100 | P8: 1 | Q8: 2 | R8: SI | | BATERÍAS: 4 | S8: LOS ALIMENTOS SE PREPARAN FUERA DEL ALOJAMIENTO O NO EXISTE PREPARACIÓN EN SITIO. | T8: SIN AGRESIONES ANIMALES NI PRESENCIA DE PLAGAS/ROEDORES DOCUMENTADA. | U8: LOS ALIMENTOS SON PREPARADOS Y SUMINISTRADOS POR LA ALCALDÍA A TRAVÉS DE RESTAURANTE EN RECIPIENTES DE ICOPOR | V8: REGISTRO DE ESTADO SANITARIO DE ESTABLECIMIENTOS.XLSX
A9: ATI-008 | B9: ARO NORTE - CARTAGO | C9: OBANDO | D9: CASETA COMUNAL - PUERTO MOLINA | E9: OCUPADO AL MOMENTO DE LA VISITA | F9: 46246 | G9: 5 | H9: NO EVALUADO | I9: NO CONCLUYENTE | J9: NO EVALUADO | K9: NO CONCLUYENTE | L9: NO EVALUADO | M9: NO CONCLUYENTE | N9: NO CONCLUYENTE | O9: 0 | P9: 1 | Q9: 0 | R9: NO DOCUMENTADO | | BATERÍAS: | S9: SIN INFORMACIÓN SUFICIENTE SOBRE PREPARACIÓN/MANIPULACIÓN DE ALIMENTOS. | T9: SIN INFORMACIÓN SUFICIENTE SOBRE VECTORES/ZOONOSIS. | U9: LA FUENTE NO DOCUMENTA LAS TRES LÍNEAS SANITARIAS CON DETALLE. | V9: INFORME AREAS OPERATIVAS-EIS -REGISTRO FOTOGRAFICO AGOSTO 24-2026.DOCX
A10: ATI-009 | B10: ARO NORTE - CARTAGO | C10: OBANDO | D10: CENTRO DE PENSAMIENTO INFANTIL | E10: HABILITADO SIN OCUPACIÓN AL REGISTRO | F10: 46246 | G10: 0 | H10: NO EVALUADO | I10: NO CONCLUYENTE | J10: NO EVALUADO | K10: NO CONCLUYENTE | L10: NO EVALUADO | M10: NO CONCLUYENTE | N10: NO CONCLUYENTE | O10: 0 | P10: 1 | Q10: 0 | R10: NO DOCUMENTADO | | BATERÍAS: | S10: SIN INFORMACIÓN SUFICIENTE SOBRE PREPARACIÓN/MANIPULACIÓN DE ALIMENTOS. | T10: SIN INFORMACIÓN SUFICIENTE SOBRE VECTORES/ZOONOSIS. | U10: HABILITADO SIN OCUPACIÓN DOCUMENTADA. | V10: INFORME AREAS OPERATIVAS-EIS -REGISTRO FOTOGRAFICO AGOSTO 24-2026.DOCX + REGISTRO EIS
A11: ATI-010 | B11: ARO CENTRO - TULUÁ | C11: RESTREPO | D11: VIVIENDA ACONDICIONADA DETRÁS DEL COLISEO MUNICIPAL | E11: ESTADO OPERATIVO NO CONCLUYENTE | F11: 46253 | H11: SIN HALLAZGOS RELEVANTES | I11: BAJA | J11: CON INFORMACIÓN PARCIAL | K11: MEDIA | L11: CON OBSERVACIONES | M11: MEDIA | N11: MEDIA | O11: 100 | P11: 1 | Q11: 10 | R11: SI | | BATERÍAS: 5 | S11: INFORMACIÓN PARCIAL DE ALIMENTOS; REQUIERE VERIFICACIÓN COMPLEMENTARIA. | T11: SE DOCUMENTAN 6 ANIMALES EN EL ALOJAMIENTO; REQUIERE VIGILANCIA ZOONÓTICA. | V11: REGISTRO DE ESTADO SANITARIO DE ESTABLECIMIENTOS.XLSX
A12: ATI-011 | B12: ARO CENTRO - TULUÁ | C12: RIOFRÍO | D12: I.E. NEMESIO RODRÍGUEZ ESCOBAR - SEDE PRINCIPAL (FENICIA) | E12: OCUPADO AL MOMENTO DE LA VISITA | F12: 46246 | G12: 16 | H12: SIN HALLAZGOS RELEVANTES | I12: BAJA | J12: CON INFORMACIÓN PARCIAL | K12: MEDIA | L12: CON OBSERVACIONES | M12: MEDIA | N12: MEDIA | O12: 100 | P12: 1 | Q12: 0 | R12: SI | | BATERÍAS: SIN DATO | S12: INFORMACIÓN PARCIAL DE ALIMENTOS; REQUIERE VERIFICACIÓN COMPLEMENTARIA. | T12: SE DOCUMENTAN 4 ANIMALES EN EL ALOJAMIENTO; REQUIERE VIGILANCIA ZOONÓTICA. | V12: REGISTRO DE ESTADO SANITARIO DE ESTABLECIMIENTOS.XLSX
A13: ATI-012 | B13: ARO NORTE - CARTAGO | C13: ROLDANILLO | D13: COLISEO IVÁN MUÑOZ VILLA | E13: TRASLADADO POR RIESGO/AFECTACIÓN | F13: 46246 | G13: 32 | H13: HALLAZGO RELEVANTE | I13: ALTA | J13: SIN PREPARACIÓN EN SITIO | K13: BAJA | L13: SIN HALLAZGOS RELEVANTES | M13: BAJA | N13: ALTA | O13: 100 | P13: 1 | Q13: 0 | R13: NO | | BATERÍAS: 2 | S13: LOS ALIMENTOS SE PREPARAN FUERA DEL ALOJAMIENTO O NO EXISTE PREPARACIÓN EN SITIO. | T13: SIN AGRESIONES ANIMALES NI PRESENCIA DE PLAGAS/ROEDORES DOCUMENTADA. | U13: LOS ALIMENTOS SON PREPARADOS Y SUMINISTRADOS POR LA ALCALDÍA A TRAVÉS DE RESTAURANTE EN RECIPIENTES DE ICOPOR. EL DÍA DE LA VISITA, HABÍAN 32 PERSONAS EN EL COLISEO, ESTOS FUERON REUBICADOS A UNA INSTITUCIÓN EDUCATIVA POR RIESGO Y A LA FECHA DE HOY 13 DE AGOSTO, YA SON MAS DE 100 PERSONAS | V13: REGISTRO DE ESTADO SANITARIO DE ESTABLECIMIENTOS.XLSX
A14: ATI-013 | B14: ARO NORTE - CARTAGO | C14: ROLDANILLO | D14: COLISEO NUESTRA SEÑORA DE CHIQUINQUIRÁ | E14: SITIO DE SEGUIMIENTO POSTERIOR A REUBICACIÓN | F14: 46254 | G14: SIN DATO | H14: SIN HALLAZGOS RELEVANTES | I14: BAJA | J14: SIN HALLAZGOS RELEVANTES | K14: BAJA | L14: NO EVALUADO | M14: NO CONCLUYENTE | N14: BAJA | O14: 67 | P14: 1 | Q14: 0 | R14: SÍ | ALCANTARILLADO; 10 BATERÍAS SANITARIAS (4 HOMBRES, 6 MUJERES). | BATERÍAS: 10 | S14: ÁREA DE PREPARACIÓN EVALUADA SIN HALLAZGO CRÍTICO DOCUMENTADO. | T14: SIN INFORMACIÓN SUFICIENTE SOBRE VECTORES/ZOONOSIS. | U14: INFORMACIÓN DIRECTA DE LISTA DE CHEQUEO DEL 20/08; POBLACIÓN TOTAL NO SE TRANSCRIBE POR BAJA LEGIBILIDAD. | V14: ALBERGUE TEMPORAL COLISEO SEÑORA CHINQUINQUIRA, MUNICIPIO ROLDANILLO.20-08-2026.PDF
A15: ATI-014 | B15: ARO CENTRO - TULUÁ | C15: SEVILLA | D15: ALOJAMIENTO TEMPORAL MUNICIPAL DE SEVILLA | E15: OCUPADO AL MOMENTO DE LA VISITA | F15: 46248 | G15: 10 | H15: SIN HALLAZGOS RELEVANTES | I15: BAJA | J15: CON OBSERVACIONES | K15: MEDIA | L15: SIN HALLAZGOS RELEVANTES | M15: BAJA | N15: MEDIA | O15: 100 | P15: 1 | Q15: 0 | R15: SI | | BATERÍAS: 12 | S15: ÁREA DE ENTREGA DE ALIMENTOS IMPROVISADA; REQUIERE CONTROL HIGIÉNICO. | T15: SIN AGRESIONES ANIMALES NI PRESENCIA DE PLAGAS/ROEDORES DOCUMENTADA. | U15: EL ÁREA DE ENTREGA DE ALIMENTOS SE ENCUENTRA IMPROVISADA CON MESAS, GRADAS, ALIMENTOS DE CONSUMO INMEDIATO, ENTREGADOS EN RECIPIENTES DESECHABLES, NO HAY PREPARACIÓN DE ALIMENTOS. LA RECOLECCIÓN DE LOS RESIDUOS SE HACE A TRAVÉS DE IDEAS S.A E.S.P | V15: REGISTRO DE ESTADO SANITARIO DE ESTABLECIMIENTOS.XLSX
A16: ATI-015 | B16: ARO NORTE - CARTAGO | C16: VERSALLES | D16: COLISEO CUBIERTO MARÍA ISABEL CRUZ | E16: USO INTERMITENTE / PERNOCTA | F16: 46247 | G16: 11 | H16: CON OBSERVACIONES | I16: MEDIA | J16: CON INFORMACIÓN PARCIAL | K16: MEDIA | L16: SIN HALLAZGOS RELEVANTES | M16: BAJA | N16: MEDIA | O16: 100 | P16: 1 | Q16: 3 | R16: SI - INTERMITENTE | | BATERÍAS: 9 | S16: INFORMACIÓN PARCIAL DE ALIMENTOS; REQUIERE VERIFICACIÓN COMPLEMENTARIA. | T16: SIN AGRESIONES ANIMALES NI PRESENCIA DE PLAGAS/ROEDORES DOCUMENTADA. | U16: EL SUMINISTRO DE AGUA POTABLE ES INTERMITENTE, LAS PERSONAS NO PERMANECEN EN EL LUGAR Y VARÍA EL NÚMERO DE PERSONAS, EL LUGAR LO UTILIZAN PARA PERNOCTAR. LOS ALIMENTOS SON SUMINISTRADOS POR LA COMUNIDAD. | V16: REGISTRO DE ESTADO SANITARIO DE ESTABLECIMIENTOS.XLSX
A17: ATI-016 | B17: ARO CENTRO - TULUÁ | C17: YOTOCO | D17: COLISEO POLIDEPORTIVO ZAWADSKI | E17: OCUPADO AL MOMENTO DE LA VISITA | F17: 46248 | G17: 50 | H17: SIN HALLAZGOS RELEVANTES | I17: BAJA | J17: SIN PREPARACIÓN EN SITIO | K17: BAJA | L17: SIN HALLAZGOS RELEVANTES | M17: BAJA | N17: BAJA | O17: 100 | P17: 1 | Q17: 2 | R17: SI | | BATERÍAS: 3 | S17: LOS ALIMENTOS SE PREPARAN FUERA DEL ALOJAMIENTO O NO EXISTE PREPARACIÓN EN SITIO. | T17: SIN AGRESIONES ANIMALES NI PRESENCIA DE PLAGAS/ROEDORES DOCUMENTADA. | U17: LOS ALIMENTOS SON PREPARADOS EN EL CENTRO VIDA Y SE ENTREGAN DE INMEDIATO EN EL ALBERGUE | V17: REGISTRO DE ESTADO SANITARIO DE ESTABLECIMIENTOS.XLSX
A18: ATI-017 | B18: ARO CENTRO - TULUÁ | C18: ZARZAL | D18: ESTADIO MUNICIPAL DE ZARZAL | E18: OCUPADO AL MOMENTO DE LA VISITA | F18: 46247 | G18: 6 | H18: SIN HALLAZGOS RELEVANTES | I18: BAJA | J18: SIN PREPARACIÓN EN SITIO | K18: BAJA | L18: SIN HALLAZGOS RELEVANTES | M18: BAJA | N18: BAJA | O18: 100 | P18: 1 | Q18: 4 | R18: SI | SI | BATERÍAS: SD | S18: LOS ALIMENTOS SE PREPARAN FUERA DEL ALOJAMIENTO O NO EXISTE PREPARACIÓN EN SITIO. | T18: SIN AGRESIONES ANIMALES NI PRESENCIA DE PLAGAS/ROEDORES DOCUMENTADA. | U18: LOS ALIMENTOS SON LLEVADOS YA PREPARADOS AL ALBERGUE. ESTE ALBERGUE FUE TRASLADO DE LA SECRETARIA DE SALUD AL ESTADIO | V18: REGISTRO DE ESTADO SANITARIO DE ESTABLECIMIENTOS.XLSX
A19: ATI-018 | B19: ARO CENTRO - TULUÁ | C19: ZARZAL | D19: PRIMER PISO DIRECCIÓN LOCAL DE SALUD | E19: OCUPADO AL MOMENTO DE LA VISITA | F19: 46246 | G19: 11 | H19: CON INFORMACIÓN PARCIAL | I19: MEDIA | J19: CON INFORMACIÓN PARCIAL | K19: MEDIA | L19: SIN HALLAZGOS RELEVANTES | M19: BAJA | N19: MEDIA | O19: 100 | P19: 1 | Q19: 3 | R19: SI | | BATERÍAS: | S19: INFORMACIÓN PARCIAL DE ALIMENTOS; REQUIERE VERIFICACIÓN COMPLEMENTARIA. | T19: NO SE DOCUMENTAN ANIMALES DOMÉSTICOS; SIN HALLAZGO VECTORIAL REPORTADO. | V19: REGISTRO DE ESTADO SANITARIO DE ESTABLECIMIENTOS.XLSX

Sheet VISITAS_ATI
A1: ID visita | B1: ID ATI | C1: ARO | D1: Municipio | E1: Establecimiento | F1: Fecha | G1: Población | H1: Mujeres | I1: Hombres | J1: Niños | K1: Niñas | L1: Agua disponible | M1: Fuente agua | N1: Sanitarios separados | O1: Baterías | P1: Animales | Q1: Felinos | R1: Caninos | S1: Otros animales | T1: Agresiones animales | U1: Área prep. alimentos | V1: Área limpia | W1: Rotulado | X1: Evita contaminación cruzada | Y1: Locativo estado | Z1: Locativo prioridad | AA1: Alimentos estado | AB1: Alimentos prioridad | AC1: Vectores estado | AD1: Vectores prioridad | AE1: Prioridad global | AF1: Cobertura % | AG1: Observaciones | AH1: Fuente | AI1: Tipo fuente
A2: ATIV-001 | B2: ATI-001 | C2: ARO NORTE - CARTAGO | D2: ANSERMANUEVO | E2: ALCALDÍA MUNICIPAL DE ANSERMANUEVO | F2: 46255 | G2: 25 | J2: 0 | K2: 0 | L2: SÍ | M2: ACUAVALLE S.A. E.S.P. | N2: SÍ | O2: 6 | P2: NO | Q2: 0 | R2: 0 | S2: 0 | T2: NO | U2: SÍ | V2: SÍ | W2: SÍ | X2: SÍ | Y2: SIN HALLAZGOS RELEVANTES | Z2: BAJA | AA2: SIN HALLAZGOS RELEVANTES | AB2: BAJA | AC2: SIN HALLAZGOS RELEVANTES | AD2: BAJA | AE2: BAJA | AF2: 100 | AG2: POBLACIÓN APROXIMADA Y VARIABLES SANITARIAS TRANSCRITAS DE LISTA DE CHEQUEO DIRECTA DEL 21/08. | AH2: ALBERGUE TEMPORAL ALCALDIA MUNICIPAL, MUNICIPIO ANSERMANUEVO.21-08-2026.PDF | AI2: CARPETA MUNICIPAL / LISTA DE CHEQUEO
A3: ATIV-002 | B3: ATI-002 | C3: ARO NORTE - CARTAGO | D3: ANSERMANUEVO | E3: PARQUE RECREACIONAL | F3: 46246 | G3: 0 | L3: NO DOCUMENTADO | N3: NO DOCUMENTADO | P3: NO DOCUMENTADO | T3: NO DOCUMENTADO | U3: NO DOCUMENTADO | Y3: NO EVALUADO | Z3: NO CONCLUYENTE | AA3: NO EVALUADO | AB3: NO CONCLUYENTE | AC3: NO EVALUADO | AD3: NO CONCLUYENTE | AE3: NO CONCLUYENTE | AF3: 0 | AG3: EL MUNICIPIO REGISTRÓ SEGUIMIENTO POSTERIOR EN ALCALDÍA MUNICIPAL. | AH3: REGISTRO EIS / CARPETA MUNICIPAL ANSERMANUEVO | AI3: BASE EIS / CARPETA MUNICIPAL
A4: ATIV-003 | B4: ATI-003 | C4: ARO CENTRO - TULUÁ | D4: CAICEDONIA | E4: COLISEO CIC - CAICEDONIA | F4: 46248 | G4: 9 | H4: 2 | I4: 3 | J4: 3 | K4: 1 | L4: SI | M4: ACUAVALLE | N4: SI | O4: 2 | P4: SI | Q4: 0 | R4: 1 | S4: 0 | T4: NO | U4: SI | V4: SI | W4: SI | X4: SI | Y4: SIN HALLAZGOS RELEVANTES | Z4: BAJA | AA4: SIN HALLAZGOS RELEVANTES | AB4: BAJA | AC4: SIN HALLAZGOS RELEVANTES | AD4: BAJA | AE4: BAJA | AF4: 100 | AG4: ALBERGA A PERSONAS, LA ALIMENTACIÓN ES SUMINISTRADA POR LA ALCALDÍA, DESARROLLO SOCIAL, A TRAVÉS DEL ANCIANATO. FUNCIONA EN EL COLISEO CIC, TIENE AGUA POTABLE Y RECOLECCIÓN DE RESIDUOS | AH4: REGISTRO DE ESTADO SANITARIO DE ESTABLECIMIENTOS.XLSX | AI4: BASE EIS UESVALLE
A5: ATIV-004 | B5: ATI-004 | C5: ARO CENTRO - TULUÁ | D5: CALIMA | E5: CIC - CENTRO DE INTEGRACIÓN CIUDADANA | F5: 46245 | G5: 22 | J5: 3 | K5: 2 | L5: SI | M5: ACUAVALLE | P5: NO | Q5: 0 | R5: 0 | S5: 0 | T5: NO | U5: SI | V5: SI | W5: SI | X5: NO | Y5: CON INFORMACIÓN PARCIAL | Z5: MEDIA | AA5: HALLAZGO RELEVANTE | AB5: ALTA | AC5: SIN HALLAZGOS RELEVANTES | AD5: BAJA | AE5: ALTA | AF5: 100 | AG5: CUENTA CON ENERGIA ´POR MEDIO DE UNA PLANTA ELECTRICA. | AH5: REGISTRO DE ESTADO SANITARIO DE ESTABLECIMIENTOS.XLSX | AI5: BASE EIS UESVALLE
A6: ATIV-005 | B6: ATI-004 | C6: ARO CENTRO - TULUÁ | D6: CALIMA | E6: CIC - CENTRO DE INTEGRACIÓN CIUDADANA | F6: 46248 | G6: 50 | H6: 18 | I6: 21 | J6: 6 | K6: 5 | L6: SI | M6: EMCALIMA | N6: SI | O6: 6 | P6: NO | Q6: 0 | R6: 0 | S6: 0 | T6: NO | U6: SI | V6: SI | W6: SI | X6: SI | Y6: SIN HALLAZGOS RELEVANTES | Z6: BAJA | AA6: HALLAZGO RELEVANTE | AB6: ALTA | AC6: SIN HALLAZGOS RELEVANTES | AD6: BAJA | AE6: ALTA | AF6: 100 | AG6: ELEMENTOS DE PROTECCIÓN PERSONAL INCOMPLETOS Y NO SE REALIZA LAVADO DE MANOS | AH6: REGISTRO DE ESTADO SANITARIO DE ESTABLECIMIENTOS.XLSX | AI6: BASE EIS UESVALLE
A7: ATIV-006 | B7: ATI-005 | C7: ARO NORTE - CARTAGO | D7: EL ÁGUILA | E7: COLEGIO PARROQUIAL EL ÁGUILA | F7: 46252 | G7: 9 | H7: 3 | I7: 3 | J7: 0 | K7: 3 | L7: SÍ | M7: RED LOCAL / SUMINISTRO CONTINUO CONSIGNADO EN LISTA DE CHEQUEO | N7: SÍ | O7: 4 | P7: NO | Q7: 0 | R7: 0 | S7: 0 | T7: NO | U7: NO | V7: NO APLICA | W7: NO APLICA | X7: NO APLICA | Y7: SIN HALLAZGOS RELEVANTES | Z7: BAJA | AA7: SIN PREPARACIÓN EN SITIO | AB7: BAJA | AC7: SIN HALLAZGOS RELEVANTES | AD7: BAJA | AE7: BAJA | AF7: 100 | AG7: DATOS TRANSCRITOS DE LISTA DE CHEQUEO DIRECTA. DISTRIBUCIÓN POR SEXO/EDAD TOMADA DE LECTURA VISUAL DEL FORMATO. | AH7: ALBERGUE TEMPORAL COLEGIO PARROQUIAL, MUNICIPIO DEL AGUILA.18-08-2026.PDF | AI7: CARPETA MUNICIPAL / LISTA DE CHEQUEO
A8: ATIV-007 | B8: ATI-006 | C8: ARO NORTE - CARTAGO | D8: LA UNIÓN | E8: COLISEO ANGELINO GARZÓN | F8: 46246 | G8: 40 | H8: 13 | I8: 11 | J8: 7 | K8: 9 | L8: SI | M8: ACUAVALLE | N8: SI | O8: 2 | P8: SI | Q8: 0 | R8: 1 | S8: 0 | T8: NO | U8: NO | Y8: SIN HALLAZGOS RELEVANTES | Z8: BAJA | AA8: SIN PREPARACIÓN EN SITIO | AB8: BAJA | AC8: SIN HALLAZGOS RELEVANTES | AD8: BAJA | AE8: BAJA | AF8: 100 | AG8: LOS INSUMOS PARA LIMPIEZA Y DESINFECCIÓN LOS TRAEN DESDE LA ALCALDÍA Y NO SE ALMACENAN EN EL LUGAR. LOS ALIMENTOS SON SUMINISTRADOS YA PREPARADOS EMPACADOS EN DESECHABLES Y SE DISTRIBUYEN PARA SU INMEDIATO CONSUMO | AH8: REGISTRO DE ESTADO SANITARIO DE ESTABLECIMIENTOS.XLSX | AI8: BASE EIS UESVALLE
A9: ATIV-008 | B9: ATI-007 | C9: ARO NORTE - CARTAGO | D9: LA VICTORIA | E9: COLISEO CIC - VILLA MARIANA | F9: 46246 | G9: 16 | H9: 5 | I9: 3 | J9: 4 | K9: 4 | L9: SI | M9: ACUAVALLE | N9: SI | O9: 4 | P9: SI | Q9: 0 | R9: 1 | S9: 1 | T9: NO | U9: NO | Y9: SIN HALLAZGOS RELEVANTES | Z9: BAJA | AA9: SIN PREPARACIÓN EN SITIO | AB9: BAJA | AC9: SIN HALLAZGOS RELEVANTES | AD9: BAJA | AE9: BAJA | AF9: 100 | AG9: LOS ALIMENTOS SON PREPARADOS Y SUMINISTRADOS POR LA ALCALDÍA A TRAVÉS DE RESTAURANTE EN RECIPIENTES DE ICOPOR | AH9: REGISTRO DE ESTADO SANITARIO DE ESTABLECIMIENTOS.XLSX | AI9: BASE EIS UESVALLE
A10: ATIV-009 | B10: ATI-008 | C10: ARO NORTE - CARTAGO | D10: OBANDO | E10: CASETA COMUNAL - PUERTO MOLINA | F10: 46246 | G10: 5 | L10: NO DOCUMENTADO | N10: NO DOCUMENTADO | P10: NO DOCUMENTADO | T10: NO DOCUMENTADO | U10: NO DOCUMENTADO | Y10: NO EVALUADO | Z10: NO CONCLUYENTE | AA10: NO EVALUADO | AB10: NO CONCLUYENTE | AC10: NO EVALUADO | AD10: NO CONCLUYENTE | AE10: NO CONCLUYENTE | AF10: 0 | AG10: LA FUENTE NO DOCUMENTA LAS TRES LÍNEAS SANITARIAS CON DETALLE. | AH10: INFORME AREAS OPERATIVAS-EIS -REGISTRO FOTOGRAFICO AGOSTO 24-2026.DOCX | AI10: INFORME UESVALLE / CARPETA MUNICIPAL
A11: ATIV-010 | B11: ATI-009 | C11: ARO NORTE - CARTAGO | D11: OBANDO | E11: CENTRO DE PENSAMIENTO INFANTIL | F11: 46246 | G11: 0 | L11: NO DOCUMENTADO | N11: NO DOCUMENTADO | P11: NO DOCUMENTADO | T11: NO DOCUMENTADO | U11: NO DOCUMENTADO | Y11: NO EVALUADO | Z11: NO CONCLUYENTE | AA11: NO EVALUADO | AB11: NO CONCLUYENTE | AC11: NO EVALUADO | AD11: NO CONCLUYENTE | AE11: NO CONCLUYENTE | AF11: 0 | AG11: HABILITADO SIN OCUPACIÓN DOCUMENTADA. | AH11: INFORME AREAS OPERATIVAS-EIS -REGISTRO FOTOGRAFICO AGOSTO 24-2026.DOCX + REGISTRO EIS | AI11: INFORME UESVALLE / BASE EIS
A12: ATIV-011 | B12: ATI-010 | C12: ARO CENTRO - TULUÁ | D12: RESTREPO | E12: VIVIENDA ACONDICIONADA DETRÁS DEL COLISEO MUNICIPAL | F12: 46253 | J12: 5 | K12: 9 | L12: SI | M12: ACUEDUCTO | N12: SI | O12: 5 | P12: SI | Q12: 0 | R12: 6 | S12: 0 | T12: NO | U12: NO | V12: NO APLICA | Y12: SIN HALLAZGOS RELEVANTES | Z12: BAJA | AA12: CON INFORMACIÓN PARCIAL | AB12: MEDIA | AC12: CON OBSERVACIONES | AD12: MEDIA | AE12: MEDIA | AF12: 100 | AH12: REGISTRO DE ESTADO SANITARIO DE ESTABLECIMIENTOS.XLSX | AI12: BASE EIS UESVALLE
A13: ATIV-012 | B13: ATI-011 | C13: ARO CENTRO - TULUÁ | D13: RIOFRÍO | E13: I.E. NEMESIO RODRÍGUEZ ESCOBAR - SEDE PRINCIPAL (FENICIA) | F13: 46246 | G13: 16 | H13: 6 | I13: 4 | J13: 2 | K13: 4 | L13: SI | M13: ACUAFENICIA | N13: SI | O13: SIN DATO | P13: SI | Q13: 1 | R13: 3 | S13: 0 | T13: NO | U13: NO | V13: NO APLICA | Y13: SIN HALLAZGOS RELEVANTES | Z13: BAJA | AA13: CON INFORMACIÓN PARCIAL | AB13: MEDIA | AC13: CON OBSERVACIONES | AD13: MEDIA | AE13: MEDIA | AF13: 100 | AH13: REGISTRO DE ESTADO SANITARIO DE ESTABLECIMIENTOS.XLSX | AI13: BASE EIS UESVALLE
A14: ATIV-013 | B14: ATI-012 | C14: ARO NORTE - CARTAGO | D14: ROLDANILLO | E14: COLISEO IVÁN MUÑOZ VILLA | F14: 46246 | G14: 32 | L14: NO | M14: ACUAVALLE-SARABRUT | N14: SI | O14: 2 | P14: NO | Q14: 0 | R14: 0 | S14: 0 | T14: NO | U14: NO | Y14: HALLAZGO RELEVANTE | Z14: ALTA | AA14: SIN PREPARACIÓN EN SITIO | AB14: BAJA | AC14: SIN HALLAZGOS RELEVANTES | AD14: BAJA | AE14: ALTA | AF14: 100 | AG14: LOS ALIMENTOS SON PREPARADOS Y SUMINISTRADOS POR LA ALCALDÍA A TRAVÉS DE RESTAURANTE EN RECIPIENTES DE ICOPOR. EL DÍA DE LA VISITA, HABÍAN 32 PERSONAS EN EL COLISEO, ESTOS FUERON REUBICADOS A UNA INSTITUCIÓN EDUCATIVA POR RIESGO Y A LA FECHA DE HOY 13 DE AGOSTO, YA SON MAS DE 100 PERSONAS | AH14: REGISTRO DE ESTADO SANITARIO DE ESTABLECIMIENTOS.XLSX | AI14: BASE EIS UESVALLE
A15: ATIV-014 | B15: ATI-013 | C15: ARO NORTE - CARTAGO | D15: ROLDANILLO | E15: COLISEO NUESTRA SEÑORA DE CHIQUINQUIRÁ | F15: 46254 | G15: SIN DATO | L15: SÍ | M15: ACUEDUCTO / SARABRUT CONSIGNADO EN FORMATO | N15: SÍ | O15: 10 | P15: NO DOCUMENTADO | T15: NO DOCUMENTADO | U15: SÍ | V15: SÍ | W15: NO DOCUMENTADO | X15: SÍ | Y15: SIN HALLAZGOS RELEVANTES | Z15: BAJA | AA15: SIN HALLAZGOS RELEVANTES | AB15: BAJA | AC15: NO EVALUADO | AD15: NO CONCLUYENTE | AE15: BAJA | AF15: 67 | AG15: INFORMACIÓN DIRECTA DE LISTA DE CHEQUEO DEL 20/08; POBLACIÓN TOTAL NO SE TRANSCRIBE POR BAJA LEGIBILIDAD. | AH15: ALBERGUE TEMPORAL COLISEO SEÑORA CHINQUINQUIRA, MUNICIPIO ROLDANILLO.20-08-2026.PDF | AI15: CARPETA MUNICIPAL / LISTA DE CHEQUEO
A16: ATIV-015 | B16: ATI-014 | C16: ARO CENTRO - TULUÁ | D16: SEVILLA | E16: ALOJAMIENTO TEMPORAL MUNICIPAL DE SEVILLA | F16: 46248 | G16: 10 | H16: 4 | I16: 3 | J16: 2 | K16: 1 | L16: SI | M16: ACUEDUCTO MUNICIPAL | N16: SI | O16: 12 | P16: SI | Q16: 0 | R16: 1 | S16: 0 | T16: NO | U16: NO | V16: NO APLICA | W16: NO APLICA | X16: NO APLICA | Y16: SIN HALLAZGOS RELEVANTES | Z16: BAJA | AA16: CON OBSERVACIONES | AB16: MEDIA | AC16: SIN HALLAZGOS RELEVANTES | AD16: BAJA | AE16: MEDIA | AF16: 100 | AG16: EL ÁREA DE ENTREGA DE ALIMENTOS SE ENCUENTRA IMPROVISADA CON MESAS, GRADAS, ALIMENTOS DE CONSUMO INMEDIATO, ENTREGADOS EN RECIPIENTES DESECHABLES, NO HAY PREPARACIÓN DE ALIMENTOS. LA RECOLECCIÓN DE LOS RESIDUOS SE HACE A TRAVÉS DE IDEAS S.A E.S.P | AH16: REGISTRO DE ESTADO SANITARIO DE ESTABLECIMIENTOS.XLSX | AI16: BASE EIS UESVALLE
A17: ATIV-016 | B17: ATI-015 | C17: ARO NORTE - CARTAGO | D17: VERSALLES | E17: COLISEO CUBIERTO MARÍA ISABEL CRUZ | F17: 46247 | G17: 11 | H17: 2 | I17: 3 | J17: 4 | K17: 2 | L17: SI - INTERMITENTE | M17: SIN DATO | N17: SI | O17: 9 | P17: SI | Q17: 0 | R17: 1 | S17: 0 | T17: NO | U17: NO | Y17: CON OBSERVACIONES | Z17: MEDIA | AA17: CON INFORMACIÓN PARCIAL | AB17: MEDIA | AC17: SIN HALLAZGOS RELEVANTES | AD17: BAJA | AE17: MEDIA | AF17: 100 | AG17: EL SUMINISTRO DE AGUA POTABLE ES INTERMITENTE, LAS PERSONAS NO PERMANECEN EN EL LUGAR Y VARÍA EL NÚMERO DE PERSONAS, EL LUGAR LO UTILIZAN PARA PERNOCTAR. LOS ALIMENTOS SON SUMINISTRADOS POR LA COMUNIDAD. | AH17: REGISTRO DE ESTADO SANITARIO DE ESTABLECIMIENTOS.XLSX | AI17: BASE EIS UESVALLE
A18: ATIV-017 | B18: ATI-016 | C18: ARO CENTRO - TULUÁ | D18: YOTOCO | E18: COLISEO POLIDEPORTIVO ZAWADSKI | F18: 46248 | G18: 50 | H18: 21 | I18: 21 | J18: 5 | K18: 3 | L18: SI | M18: ACUAVALLE | N18: SI | O18: 3 | P18: NO | Q18: 0 | R18: 0 | S18: 0 | T18: NO APLICA | U18: NO | V18: NO APLICA | W18: NO APLICA | X18: NO APLICA | Y18: SIN HALLAZGOS RELEVANTES | Z18: BAJA | AA18: SIN PREPARACIÓN EN SITIO | AB18: BAJA | AC18: SIN HALLAZGOS RELEVANTES | AD18: BAJA | AE18: BAJA | AF18: 100 | AG18: LOS ALIMENTOS SON PREPARADOS EN EL CENTRO VIDA Y SE ENTREGAN DE INMEDIATO EN EL ALBERGUE | AH18: REGISTRO DE ESTADO SANITARIO DE ESTABLECIMIENTOS.XLSX | AI18: BASE EIS UESVALLE
A19: ATIV-018 | B19: ATI-017 | C19: ARO CENTRO - TULUÁ | D19: ZARZAL | E19: ESTADIO MUNICIPAL DE ZARZAL | F19: 46247 | G19: 6 | H19: SD | I19: SD | J19: 2 | K19: 1 | L19: SI | M19: ACUAVALLE | N19: SI | O19: SD | P19: NO | Q19: 0 | R19: 0 | S19: 0 | T19: NO APLICA | U19: NO | V19: NO APLICA | W19: NO APLICA | X19: NO APLICA | Y19: SIN HALLAZGOS RELEVANTES | Z19: BAJA | AA19: SIN PREPARACIÓN EN SITIO | AB19: BAJA | AC19: SIN HALLAZGOS RELEVANTES | AD19: BAJA | AE19: BAJA | AF19: 100 | AG19: LOS ALIMENTOS SON LLEVADOS YA PREPARADOS AL ALBERGUE. ESTE ALBERGUE FUE TRASLADO DE LA SECRETARIA DE SALUD AL ESTADIO | AH19: REGISTRO DE ESTADO SANITARIO DE ESTABLECIMIENTOS.XLSX | AI19: BASE EIS UESVALLE
A20: ATIV-019 | B20: ATI-018 | C20: ARO CENTRO - TULUÁ | D20: ZARZAL | E20: PRIMER PISO DIRECCIÓN LOCAL DE SALUD | F20: 46246 | G20: 11 | H20: 2 | I20: 2 | J20: 4 | K20: 3 | L20: SI | M20: ACUAVALLE | P20: NO | Q20: 0 | R20: 0 | S20: 0 | U20: NO | V20: NO APLICA | Y20: CON INFORMACIÓN PARCIAL | Z20: MEDIA | AA20: CON INFORMACIÓN PARCIAL | AB20: MEDIA | AC20: SIN HALLAZGOS RELEVANTES | AD20: BAJA | AE20: MEDIA | AF20: 100 | AH20: REGISTRO DE ESTADO SANITARIO DE ESTABLECIMIENTOS.XLSX | AI20: BASE EIS UESVALLE

Sheet RESUMEN_MUNICIPAL
A1: Municipio | B1: Cementerios | C1: Cementerio Alta/Crítica | D1: Cementerio con restricción | E1: Alojamiento Temporal | F1: ATI Alta/Crítica | G1: ATI No concluyente | H1: ATI Población documentada
A2: Alcalá | B2: =COUNTIF(CEMENTERIOS!C:C,A2) -> 1 | C2: =COUNTIFS(CEMENTERIOS!C:C,A2,CEMENTERIOS!G:G,"Alta")+COUNTIFS(CEMENTERIOS!C:C,A2,CEMENTERIOS!G:G,"Crítica") -> 1 | D2: =COUNTIFS(CEMENTERIOS!C:C,A2,CEMENTERIOS!H:H,"<>")+0 -> 1 | E2: =COUNTIF(ALOJAMIENTO_TEMPORAL!C:C,A2) -> 0 | F2: =COUNTIFS(ALOJAMIENTO_TEMPORAL!C:C,A2,ALOJAMIENTO_TEMPORAL!N:N,"Alta")+COUNTIFS(ALOJAMIENTO_TEMPORAL!C:C,A2,ALOJAMIENTO_TEMPORAL!N:N,"Crítica") -> 0 | G2: =COUNTIFS(ALOJAMIENTO_TEMPORAL!C:C,A2,ALOJAMIENTO_TEMPORAL!N:N,"No concluyente") -> 0 | H2: =SUMIF(ALOJAMIENTO_TEMPORAL!C:C,A2,ALOJAMIENTO_TEMPORAL!G:G) -> 0
A3: Ansermanuevo | B3: =COUNTIF(CEMENTERIOS!C:C,A3) -> 1 | C3: =COUNTIFS(CEMENTERIOS!C:C,A3,CEMENTERIOS!G:G,"Alta")+COUNTIFS(CEMENTERIOS!C:C,A3,CEMENTERIOS!G:G,"Crítica") -> 0 | D3: =COUNTIFS(CEMENTERIOS!C:C,A3,CEMENTERIOS!H:H,"<>")+0 -> 1 | E3: =COUNTIF(ALOJAMIENTO_TEMPORAL!C:C,A3) -> 2 | F3: =COUNTIFS(ALOJAMIENTO_TEMPORAL!C:C,A3,ALOJAMIENTO_TEMPORAL!N:N,"Alta")+COUNTIFS(ALOJAMIENTO_TEMPORAL!C:C,A3,ALOJAMIENTO_TEMPORAL!N:N,"Crítica") -> 0 | G3: =COUNTIFS(ALOJAMIENTO_TEMPORAL!C:C,A3,ALOJAMIENTO_TEMPORAL!N:N,"No concluyente") -> 1 | H3: =SUMIF(ALOJAMIENTO_TEMPORAL!C:C,A3,ALOJAMIENTO_TEMPORAL!G:G) -> 25
A4: Bolívar | B4: =COUNTIF(CEMENTERIOS!C:C,A4) -> 1 | C4: =COUNTIFS(CEMENTERIOS!C:C,A4,CEMENTERIOS!G:G,"Alta")+COUNTIFS(CEMENTERIOS!C:C,A4,CEMENTERIOS!G:G,"Crítica") -> 0 | D4: =COUNTIFS(CEMENTERIOS!C:C,A4,CEMENTERIOS!H:H,"<>")+0 -> 0 | E4: =COUNTIF(ALOJAMIENTO_TEMPORAL!C:C,A4) -> 0 | F4: =COUNTIFS(ALOJAMIENTO_TEMPORAL!C:C,A4,ALOJAMIENTO_TEMPORAL!N:N,"Alta")+COUNTIFS(ALOJAMIENTO_TEMPORAL!C:C,A4,ALOJAMIENTO_TEMPORAL!N:N,"Crítica") -> 0 | G4: =COUNTIFS(ALOJAMIENTO_TEMPORAL!C:C,A4,ALOJAMIENTO_TEMPORAL!N:N,"No concluyente") -> 0 | H4: =SUMIF(ALOJAMIENTO_TEMPORAL!C:C,A4,ALOJAMIENTO_TEMPORAL!G:G) -> 0
A5: Caicedonia | B5: =COUNTIF(CEMENTERIOS!C:C,A5) -> 1 | C5: =COUNTIFS(CEMENTERIOS!C:C,A5,CEMENTERIOS!G:G,"Alta")+COUNTIFS(CEMENTERIOS!C:C,A5,CEMENTERIOS!G:G,"Crítica") -> 1 | D5: =COUNTIFS(CEMENTERIOS!C:C,A5,CEMENTERIOS!H:H,"<>")+0 -> 1 | E5: =COUNTIF(ALOJAMIENTO_TEMPORAL!C:C,A5) -> 1 | F5: =COUNTIFS(ALOJAMIENTO_TEMPORAL!C:C,A5,ALOJAMIENTO_TEMPORAL!N:N,"Alta")+COUNTIFS(ALOJAMIENTO_TEMPORAL!C:C,A5,ALOJAMIENTO_TEMPORAL!N:N,"Crítica") -> 0 | G5: =COUNTIFS(ALOJAMIENTO_TEMPORAL!C:C,A5,ALOJAMIENTO_TEMPORAL!N:N,"No concluyente") -> 0 | H5: =SUMIF(ALOJAMIENTO_TEMPORAL!C:C,A5,ALOJAMIENTO_TEMPORAL!G:G) -> 9
A6: Calima | B6: =COUNTIF(CEMENTERIOS!C:C,A6) -> 1 | C6: =COUNTIFS(CEMENTERIOS!C:C,A6,CEMENTERIOS!G:G,"Alta")+COUNTIFS(CEMENTERIOS!C:C,A6,CEMENTERIOS!G:G,"Crítica") -> 1 | D6: =COUNTIFS(CEMENTERIOS!C:C,A6,CEMENTERIOS!H:H,"<>")+0 -> 0 | E6: =COUNTIF(ALOJAMIENTO_TEMPORAL!C:C,A6) -> 1 | F6: =COUNTIFS(ALOJAMIENTO_TEMPORAL!C:C,A6,ALOJAMIENTO_TEMPORAL!N:N,"Alta")+COUNTIFS(ALOJAMIENTO_TEMPORAL!C:C,A6,ALOJAMIENTO_TEMPORAL!N:N,"Crítica") -> 1 | G6: =COUNTIFS(ALOJAMIENTO_TEMPORAL!C:C,A6,ALOJAMIENTO_TEMPORAL!N:N,"No concluyente") -> 0 | H6: =SUMIF(ALOJAMIENTO_TEMPORAL!C:C,A6,ALOJAMIENTO_TEMPORAL!G:G) -> 50
A7: Dagua | B7: =COUNTIF(CEMENTERIOS!C:C,A7) -> 8 | C7: =COUNTIFS(CEMENTERIOS!C:C,A7,CEMENTERIOS!G:G,"Alta")+COUNTIFS(CEMENTERIOS!C:C,A7,CEMENTERIOS!G:G,"Crítica") -> 2 | D7: =COUNTIFS(CEMENTERIOS!C:C,A7,CEMENTERIOS!H:H,"<>")+0 -> 4 | E7: =COUNTIF(ALOJAMIENTO_TEMPORAL!C:C,A7) -> 0 | F7: =COUNTIFS(ALOJAMIENTO_TEMPORAL!C:C,A7,ALOJAMIENTO_TEMPORAL!N:N,"Alta")+COUNTIFS(ALOJAMIENTO_TEMPORAL!C:C,A7,ALOJAMIENTO_TEMPORAL!N:N,"Crítica") -> 0 | G7: =COUNTIFS(ALOJAMIENTO_TEMPORAL!C:C,A7,ALOJAMIENTO_TEMPORAL!N:N,"No concluyente") -> 0 | H7: =SUMIF(ALOJAMIENTO_TEMPORAL!C:C,A7,ALOJAMIENTO_TEMPORAL!G:G) -> 0
A8: El Cerrito | B8: =COUNTIF(CEMENTERIOS!C:C,A8) -> 4 | C8: =COUNTIFS(CEMENTERIOS!C:C,A8,CEMENTERIOS!G:G,"Alta")+COUNTIFS(CEMENTERIOS!C:C,A8,CEMENTERIOS!G:G,"Crítica") -> 0 | D8: =COUNTIFS(CEMENTERIOS!C:C,A8,CEMENTERIOS!H:H,"<>")+0 -> 4 | E8: =COUNTIF(ALOJAMIENTO_TEMPORAL!C:C,A8) -> 0 | F8: =COUNTIFS(ALOJAMIENTO_TEMPORAL!C:C,A8,ALOJAMIENTO_TEMPORAL!N:N,"Alta")+COUNTIFS(ALOJAMIENTO_TEMPORAL!C:C,A8,ALOJAMIENTO_TEMPORAL!N:N,"Crítica") -> 0 | G8: =COUNTIFS(ALOJAMIENTO_TEMPORAL!C:C,A8,ALOJAMIENTO_TEMPORAL!N:N,"No concluyente") -> 0 | H8: =SUMIF(ALOJAMIENTO_TEMPORAL!C:C,A8,ALOJAMIENTO_TEMPORAL!G:G) -> 0
A9: El Dovio | B9: =COUNTIF(CEMENTERIOS!C:C,A9) -> 1 | C9: =COUNTIFS(CEMENTERIOS!C:C,A9,CEMENTERIOS!G:G,"Alta")+COUNTIFS(CEMENTERIOS!C:C,A9,CEMENTERIOS!G:G,"Crítica") -> 1 | D9: =COUNTIFS(CEMENTERIOS!C:C,A9,CEMENTERIOS!H:H,"<>")+0 -> 1 | E9: =COUNTIF(ALOJAMIENTO_TEMPORAL!C:C,A9) -> 0 | F9: =COUNTIFS(ALOJAMIENTO_TEMPORAL!C:C,A9,ALOJAMIENTO_TEMPORAL!N:N,"Alta")+COUNTIFS(ALOJAMIENTO_TEMPORAL!C:C,A9,ALOJAMIENTO_TEMPORAL!N:N,"Crítica") -> 0 | G9: =COUNTIFS(ALOJAMIENTO_TEMPORAL!C:C,A9,ALOJAMIENTO_TEMPORAL!N:N,"No concluyente") -> 0 | H9: =SUMIF(ALOJAMIENTO_TEMPORAL!C:C,A9,ALOJAMIENTO_TEMPORAL!G:G) -> 0
A10: El Águila | B10: =COUNTIF(CEMENTERIOS!C:C,A10) -> 1 | C10: =COUNTIFS(CEMENTERIOS!C:C,A10,CEMENTERIOS!G:G,"Alta")+COUNTIFS(CEMENTERIOS!C:C,A10,CEMENTERIOS!G:G,"Crítica") -> 0 | D10: =COUNTIFS(CEMENTERIOS!C:C,A10,CEMENTERIOS!H:H,"<>")+0 -> 1 | E10: =COUNTIF(ALOJAMIENTO_TEMPORAL!C:C,A10) -> 1 | F10: =COUNTIFS(ALOJAMIENTO_TEMPORAL!C:C,A10,ALOJAMIENTO_TEMPORAL!N:N,"Alta")+COUNTIFS(ALOJAMIENTO_TEMPORAL!C:C,A10,ALOJAMIENTO_TEMPORAL!N:N,"Crítica") -> 0 | G10: =COUNTIFS(ALOJAMIENTO_TEMPORAL!C:C,A10,ALOJAMIENTO_TEMPORAL!N:N,"No concluyente") -> 0 | H10: =SUMIF(ALOJAMIENTO_TEMPORAL!C:C,A10,ALOJAMIENTO_TEMPORAL!G:G) -> 9
A11: Florida | B11: =COUNTIF(CEMENTERIOS!C:C,A11) -> 3 | C11: =COUNTIFS(CEMENTERIOS!C:C,A11,CEMENTERIOS!G:G,"Alta")+COUNTIFS(CEMENTERIOS!C:C,A11,CEMENTERIOS!G:G,"Crítica") -> 0 | D11: =COUNTIFS(CEMENTERIOS!C:C,A11,CEMENTERIOS!H:H,"<>")+0 -> 3 | E11: =COUNTIF(ALOJAMIENTO_TEMPORAL!C:C,A11) -> 0 | F11: =COUNTIFS(ALOJAMIENTO_TEMPORAL!C:C,A11,ALOJAMIENTO_TEMPORAL!N:N,"Alta")+COUNTIFS(ALOJAMIENTO_TEMPORAL!C:C,A11,ALOJAMIENTO_TEMPORAL!N:N,"Crítica") -> 0 | G11: =COUNTIFS(ALOJAMIENTO_TEMPORAL!C:C,A11,ALOJAMIENTO_TEMPORAL!N:N,"No concluyente") -> 0 | H11: =SUMIF(ALOJAMIENTO_TEMPORAL!C:C,A11,ALOJAMIENTO_TEMPORAL!G:G) -> 0
A12: Ginebra | B12: =COUNTIF(CEMENTERIOS!C:C,A12) -> 3 | C12: =COUNTIFS(CEMENTERIOS!C:C,A12,CEMENTERIOS!G:G,"Alta")+COUNTIFS(CEMENTERIOS!C:C,A12,CEMENTERIOS!G:G,"Crítica") -> 1 | D12: =COUNTIFS(CEMENTERIOS!C:C,A12,CEMENTERIOS!H:H,"<>")+0 -> 3 | E12: =COUNTIF(ALOJAMIENTO_TEMPORAL!C:C,A12) -> 0 | F12: =COUNTIFS(ALOJAMIENTO_TEMPORAL!C:C,A12,ALOJAMIENTO_TEMPORAL!N:N,"Alta")+COUNTIFS(ALOJAMIENTO_TEMPORAL!C:C,A12,ALOJAMIENTO_TEMPORAL!N:N,"Crítica") -> 0 | G12: =COUNTIFS(ALOJAMIENTO_TEMPORAL!C:C,A12,ALOJAMIENTO_TEMPORAL!N:N,"No concluyente") -> 0 | H12: =SUMIF(ALOJAMIENTO_TEMPORAL!C:C,A12,ALOJAMIENTO_TEMPORAL!G:G) -> 0
A13: Guacari | B13: =COUNTIF(CEMENTERIOS!C:C,A13) -> 1 | C13: =COUNTIFS(CEMENTERIOS!C:C,A13,CEMENTERIOS!G:G,"Alta")+COUNTIFS(CEMENTERIOS!C:C,A13,CEMENTERIOS!G:G,"Crítica") -> 1 | D13: =COUNTIFS(CEMENTERIOS!C:C,A13,CEMENTERIOS!H:H,"<>")+0 -> 1 | E13: =COUNTIF(ALOJAMIENTO_TEMPORAL!C:C,A13) -> 0 | F13: =COUNTIFS(ALOJAMIENTO_TEMPORAL!C:C,A13,ALOJAMIENTO_TEMPORAL!N:N,"Alta")+COUNTIFS(ALOJAMIENTO_TEMPORAL!C:C,A13,ALOJAMIENTO_TEMPORAL!N:N,"Crítica") -> 0 | G13: =COUNTIFS(ALOJAMIENTO_TEMPORAL!C:C,A13,ALOJAMIENTO_TEMPORAL!N:N,"No concluyente") -> 0 | H13: =SUMIF(ALOJAMIENTO_TEMPORAL!C:C,A13,ALOJAMIENTO_TEMPORAL!G:G) -> 0
... A28: Zarzal | B28: =COUNTIF(CEMENTERIOS!C:C,A28) -> 1 | C28: =COUNTIFS(CEMENTERIOS!C:C,A28,CEMENTERIOS!G:G,"Alta")+COUNTIFS(CEMENTERIOS!C:C,A28,CEMENTERIOS!G:G,"Crítica") -> 1 | D28: =COUNTIFS(CEMENTERIOS!C:C,A28,CEMENTERIOS!H:H,"<>")+0 -> 0 | E28: =COUNTIF(ALOJAMIENTO_TEMPORAL!C:C,A28) -> 2 | F28: =COUNTIFS(ALOJAMIENTO_TEMPORAL!C:C,A28,ALOJAMIENTO_TEMPORAL!N:N,"Alta")+COUNTIFS(ALOJAMIENTO_TEMPORAL!C:C,A28,ALOJAMIENTO_TEMPORAL!N:N,"Crítica") -> 0 | G28: =COUNTIFS(ALOJAMIENTO_TEMPORAL!C:C,A28,ALOJAMIENTO_TEMPORAL!N:N,"No concluyente") -> 0 | H28: =SUMIF(ALOJAMIENTO_TEMPORAL!C:C,A28,ALOJAMIENTO_TEMPORAL!G:G) -> 17
B29: =SUBTOTAL(109,ResumenMunicipalTable[Cementerios]) -> 50 | C29: =SUBTOTAL(109,ResumenMunicipalTable[Cementerio Alta/Crítica]) -> 24 | D29: =SUBTOTAL(109,ResumenMunicipalTable[Cementerio con restricción]) -> 38 | E29: =SUBTOTAL(109,ResumenMunicipalTable[Alojamiento Temporal]) -> 18 | F29: =SUBTOTAL(109,ResumenMunicipalTable[ATI Alta/Crítica]) -> 2 | G29: =SUBTOTAL(109,G2:G28) -> 3 | H29: =SUBTOTAL(109,H2:H28) -> 290

Sheet CATALOGOS
A1: Catálogo | B1: Valor | C1: Definición operativa
A2: Nivel afectación fuente - cementerios | B2: Sin afectación / Leve / Moderada / Grave / Crítica | C2: Se conserva el valor consignado por la fuente; se normaliza solo su escritura.
A3: Prioridad sanitaria | B3: Baja | C3: Seguimiento rutinario; sin señal de alarma sanitaria inmediata.
A4: Prioridad sanitaria | B4: Media | C4: Requiere seguimiento/acción correctiva por afectación o condición sanitaria localizada.
A5: Prioridad sanitaria | B5: Alta | C5: Requiere intervención prioritaria por exposición, riesgo de colapso, afectación grave o condición sanitaria relevante.
A6: Prioridad sanitaria | B6: Crítica | C6: Atención inmediata por combinación de exposición de restos, bóvedas abiertas, riesgo mayor/no controlado o clasificación crítica de fuente.
A7: Prioridad sanitaria | B7: No concluyente | C7: Información insuficiente para clasificar.
A8: ATI - líneas | B8: Locativo/EIS | C8: Infraestructura, agua, excretas/aguas residuales, sanitarios, residuos e higiene locativa.
A9: ATI - líneas | B9: Alimentos | C9: Lugar y forma de preparación/suministro, higiene, rotulado, conservación y contaminación cruzada.
A10: ATI - líneas | B10: Vectores | C10: Vectores/roedores, condiciones favorecedoras, animales y riesgos zoonóticos.
A11: Regla ATI | B11: Prioridad global | C11: Corresponde al peor componente evaluado; la cobertura indica si faltan líneas por documentar.
